<?xml version="1.0" encoding="utf-8"?>
<!-- This URDF was automatically created by SolidWorks to URDF Exporter! Originally created by Stephen Brawner (brawner@gmail.com) 
     Commit Version: 1.6.0-4-g7f85cfe  Build Version: 1.6.7995.38578
     For more information, please see http://wiki.ros.org/sw_urdf_exporter -->
<robot
  name="robot">
  <link
    name="base">
    <inertial>
      <origin
        xyz="-0.00965481457320272 0.0111120747049655 0.0120772735216159"
        rpy="0 0 0" />
      <mass
        value="0.197321172139232" />
      <inertia
        ixx="0.000254464488119407"
        ixy="5.7773136475039E-08"
        ixz="-2.4030438420844E-07"
        iyy="0.000348452218851022"
        iyz="-4.09032412681973E-05"
        izz="0.000146305796028143" />
    </inertial>
    <visual>
      <origin
        xyz="0 0 0"
        rpy="0 0 0" />
      <geometry>
        <mesh
          filename="package://robot/meshes/base.STL" />
      </geometry>
      <material
        name="">
        <color
          rgba="0.792156862745098 0.819607843137255 0.933333333333333 1" />
      </material>
    </visual>
    <collision>
      <origin
        xyz="0 0 0"
        rpy="0 0 0" />
      <geometry>
        <mesh
          filename="package://robot/meshes/base.STL" />
      </geometry>
    </collision>
  </link>
  <link
    name="Left Wheel">
    <inertial>
      <origin
        xyz="0.015634 3.4368E-10 -7.9793E-11"
        rpy="0 0 0" />
      <mass
        value="0.30171" />
      <inertia
        ixx="0.00021617"
        ixy="-1.8513E-13"
        ixz="8.6051E-15"
        iyy="0.00011754"
        iyz="-8.418E-14"
        izz="0.00011754" />
    </inertial>
    <visual>
      <origin
        xyz="0 0 0"
        rpy="0 0 0" />
      <geometry>
        <mesh
          filename="package://robot/meshes/Left Wheel.STL" />
      </geometry>
      <material
        name="">
        <color
          rgba="0.65098 0.61961 0.58824 1" />
      </material>
    </visual>
    <collision>
      <origin
        xyz="0 0 0"
        rpy="0 0 0" />
      <geometry>
        <mesh
          filename="package://robot/meshes/Left Wheel.STL" />
      </geometry>
    </collision>
  </link>
  <joint
    name="left_wheel"
    type="continuous">
    <origin
      xyz="-0.061096 -0.051666 0.00018021"
      rpy="-2.2886 0 3.1416" />
    <parent
      link="base" />
    <child
      link="Left Wheel" />
    <axis
      xyz="1 0 0" />
  </joint>
  <link
    name="Right Wheel">
    <inertial>
      <origin
        xyz="0.015634 1.0186E-10 -2.1241E-11"
        rpy="0 0 0" />
      <mass
        value="0.30171" />
      <inertia
        ixx="0.00021617"
        ixy="6.8231E-14"
        ixz="-9.3068E-15"
        iyy="0.00011754"
        iyz="-3.8625E-13"
        izz="0.00011754" />
    </inertial>
    <visual>
      <origin
        xyz="0 0 0"
        rpy="0 0 0" />
      <geometry>
        <mesh
          filename="package://robot/meshes/Right Wheel.STL" />
      </geometry>
      <material
        name="">
        <color
          rgba="0.65098 0.61961 0.58824 1" />
      </material>
    </visual>
    <collision>
      <origin
        xyz="0 0 0"
        rpy="0 0 0" />
      <geometry>
        <mesh
          filename="package://robot/meshes/Right Wheel.STL" />
      </geometry>
    </collision>
  </link>
  <joint
    name="right_wheel"
    type="continuous">
    <origin
      xyz="0.041879 -0.051666 0.00018021"
      rpy="0.95996 0 0" />
    <parent
      link="base" />
    <child
      link="Right Wheel" />
    <axis
      xyz="1 0 0" />
  </joint>
  <link
    name="Free Wheel">
    <inertial>
      <origin
        xyz="0 0 0"
        rpy="0 0 0" />
      <mass
        value="0" />
      <inertia
        ixx="0"
        ixy="0"
        ixz="0"
        iyy="0"
        iyz="0"
        izz="0" />
    </inertial>
    <visual>
      <origin
        xyz="0 0 0"
        rpy="0 0 0" />
      <geometry>
        <mesh
          filename="package://robot/meshes/Free Wheel.STL" />
      </geometry>
      <material
        name="">
        <color
          rgba="1 1 1 1" />
      </material>
    </visual>
    <collision>
      <origin
        xyz="0 0 0"
        rpy="0 0 0" />
      <geometry>
        <mesh
          filename="package://robot/meshes/Free Wheel.STL" />
      </geometry>
    </collision>
  </link>
  <joint
    name="free_wheel"
    type="continuous">
    <origin
      xyz="-0.00945839046097954 0.0740844223621159 -0.0106197918296602"
      rpy="1.5707963267949 0 0" />
    <parent
      link="base" />
    <child
      link="Free Wheel" />
    <axis
      xyz="0 1 0" />
  </joint>
</robot>
